Workbook

Sheet Instructions
A1: Warfarin and Osteoporosis / Fragility Fractures - Data Collection Workbook
A2: Retrospective cohort study - Jordan University Hospital (JUH) & King Hussein Cancer Center (KHCC)
A4: SHEETS
A5: Patient_Data | B5: Main extraction sheet - ONE ROW PER PATIENT. 83 variables in sections A-F (colour-coded header). 1,000 rows prepared.
A6: Screening_Log | B6: Every record reviewed (eligible or not). 'Eligible' is calculated automatically. Keep de-identified.
A7: Data_Dictionary | B7: Definition, type, allowed values, source and missing-value code for every variable.
A8: Summary | B8: Live tables: recruitment vs target (151 / 302), baseline characteristics, incidence per 1,000 person-years, duration categories, missing data.
A9: Protocol_Decisions | B9: Open protocol questions to settle with the supervisor BEFORE extraction (yellow cells = record decision).
A10: Lists | B10: Drop-down values. Edit here if the supervisor changes a category.
A11: HOW TO FILL
A12: White cells | B12: Type or pick from the drop-down list.
A13: Grey cells | B13: Formulas - DO NOT type: BMI, duration category, composite outcome & date, follow-up days / person-years, age group, subgroups, T-score helper.
A14: Yellow row 3 | B14: Example patient showing the expected format. Excluded from Summary. Delete before export to SPSS.
A15: Dates | B15: dd/mm/yyyy. Hover over any header to see its definition.
A16: Missing data | B16: Distinguish 'No' from 'Unknown'. Leave numeric/date cells blank if not recorded.
A17: Two reviewers | B17: Proposal requires two independent extractors - record initials in Data_Extractor; resolve discrepancies by consensus / third reviewer.
A18: Confidentiality | B18: No names or national ID numbers in this file. Keep the Study_ID-to-MRN linkage in a separate secured file.
A19: Export to SPSS | B19: Delete the example row, delete row 1 (section band), then File > Save As CSV or open .xlsx directly in SPSS v28.
A20: تعليمات مختصرة
A21: الخلايا البيضاء | B21: اكتب أو اختر من القائمة المنسدلة.
A22: الخلايا الرمادية | B22: معادلات تُحسب تلقائياً - لا تكتب فيها.
A23: الصف الأصفر (3) | B23: مثال توضيحي فقط - احذفه قبل التحليل.
A24: قبل البدء | B24: راجع ورقة Protocol_Decisions مع المشرف (مجموعة المقارنة، شرط DEXA، الكسور السابقة).

Sheet Patient_Data
A1: A. Screening, ID & demographics | B1: A. Screening, ID & demographics | C1: A. Screening, ID & demographics | D1: A. Screening, ID & demographics | E1: A. Screening, ID & demographics | F1: A. Screening, ID & demographics | G1: A. Screening, ID & demographics | H1: A. Screening, ID & demographics | I1: A. Screening, ID & demographics | J1: A. Screening, ID & demographics | K1: A. Screening, ID & demographics | L1: A. Screening, ID & demographics | M1: B. Cardiac indication & anticoagulant exposure | N1: B. Cardiac indication & anticoagulant exposure | O1: B. Cardiac indication & anticoagulant exposure | P1: B. Cardiac indication & anticoagulant exposure | Q1: B. Cardiac indication & anticoagulant exposure | R1: B. Cardiac indication & anticoagulant exposure | S1: B. Cardiac indication & anticoagulant exposure | T1: B. Cardiac indication & anticoagulant exposure | U1: B. Cardiac indication & anticoagulant exposure | V1: B. Cardiac indication & anticoagulant exposure | W1: B. Cardiac indication & anticoagulant exposure | X1: B. Cardiac indication & anticoagulant exposure | Y1: B. Cardiac indication & anticoagulant exposure | Z1: B. Cardiac indication & anticoagulant exposure | AA1: C. Baseline eligibility & medical history | AB1: C. Baseline eligibility & medical history | AC1: C. Baseline eligibility & medical history | AD1: C. Baseline eligibility & medical history | AE1: C. Baseline eligibility & medical history | AF1: C. Baseline eligibility & medical history | AG1: C. Baseline eligibility & medical history | AH1: C. Baseline eligibility & medical history | AI1: C. Baseline eligibility & medical history | AJ1: C. Baseline eligibility & medical history | AK1: C. Baseline eligibility & medical history | AL1: C. Baseline eligibility & medical history | AM1: C. Baseline eligibility & medical history | AN1: C. Baseline eligibility & medical history | AO1: C. Baseline eligibility & medical history | AP1: C. Baseline eligibility & medical history | AQ1: C. Baseline eligibility & medical history | AR1: D. Osteoporosis & DEXA outcomes | AS1: D. Osteoporosis & DEXA outcomes | AT1: D. Osteoporosis & DEXA outcomes | AU1: D. Osteoporosis & DEXA outcomes | AV1: D. Osteoporosis & DEXA outcomes | AW1: D. Osteoporosis & DEXA outcomes | AX1: D. Osteoporosis & DEXA outcomes | AY1: D. Osteoporosis & DEXA outcomes | AZ1: D. Osteoporosis & DEXA outcomes | BA1: D. Osteoporosis & DEXA outcomes | BB1: D. Osteoporosis & DEXA outcomes | BC1: D. Osteoporosis & DEXA outcomes | BD1: D. Osteoporosis & DEXA outcomes | BE1: D. Osteoporosis & DEXA outcomes | BF1: D. Osteoporosis & DEXA outcomes | BG1: D. Osteoporosis & DEXA outcomes | BH1: D. Osteoporosis & DEXA outcomes | BI1: E. Fragility fractures & composite outcome | BJ1: E. Fragility fractures & composite outcome | BK1: E. Fragility fractures & composite outcome | BL1: E. Fragility fractures & composite outcome | BM1: E. Fragility fractures & composite outcome | BN1: E. Fragility fractures & composite outcome | BO1: E. Fragility fractures & composite outcome | BP1: F. Follow-up & analysis variables | BQ1: F. Follow-up & analysis variables | BR1: F. Follow-up & analysis variables | BS1: F. Follow-up & analysis variables | BT1: F. Follow-up & analysis variables | BU1: F. Follow-up & analysis variables | BV1: F. Follow-up & analysis variables | BW1: F. Follow-up & analysis variables | BX1: F. Follow-up & analysis variables | BY1: F. Follow-up & analysis variables | BZ1: F. Follow-up & analysis variables | CA1: F. Follow-up & analysis variables | CB1: F. Follow-up & analysis variables | CC1: F. Follow-up & analysis variables | CD1: F. Follow-up & analysis variables | CE1: F. Follow-up & analysis variables
A2: Study_ID | B2: Hospital_Source | C2: Eligible | D2: Exclusion_Reason | E2: Age_at_Index | F2: Sex | G2: Nationality | H2: Height_cm | I2: Weight_kg | J2: BMI | K2: Smoking_Status | L2: Alcohol_Use | M2: Atrial_Fibrillation | N2: Valvular_Heart_Disease | O2: Anticoagulation_Indication | P2: Anticoagulant_Group | Q2: Specific_Anticoagulant | R2: Exposure_Start_Date | S2: Exposure_End_Date | T2: Warfarin_Duration_Months | U2: Warfarin_Duration_Category | V2: Warfarin_Cumulative_Dose | W2: Mean_INR | X2: INR_Monitoring_Available | Y2: Previous_Anticoagulant_Use | Z2: Drug_Switch_or_Discontinuation_Date | AA2: Preexisting_Osteoporosis | AB2: Preexisting_Fragility_Fracture | AC2: Chronic_Kidney_Disease | AD2: Diabetes_Mellitus | AE2: Hypertension | AF2: Rheumatoid_Arthritis | AG2: Inflammatory_Bowel_Disease | AH2: Chronic_Liver_Disease | AI2: Systemic_Corticosteroid_Use | AJ2: PPI_Use | AK2: History_of_Falls | AL2: Cancer_History | AM2: Bone_Metastases | AN2: Hyperparathyroidism_or_Pagets_Disease | AO2: Other_Comorbidities | AP2: Anti_Osteoporosis_Medication | AQ2: Calcium_or_Vitamin_D | AR2: Baseline_DEXA_Available | AS2: Baseline_DEXA_Date | AT2: Baseline_Lumbar_Spine_Tscore | AU2: Baseline_Femoral_Neck_Tscore | AV2: Baseline_Total_Hip_Tscore | AW2: Baseline_BMD_Values_and_Sites | AX2: Incident_Osteoporosis | AY2: Osteoporosis_Diagnosis_Date | AZ2: Osteoporosis_Diagnostic_Method | BA2: Osteoporosis_ICD10_Code | BB2: Followup_DEXA_Date | BC2: Followup_Lumbar_Spine_Tscore | BD2: Followup_Femoral_Neck_Tscore | BE2: Followup_Total_Hip_Tscore | BF2: Followup_BMD_Values_and_Sites | BG2: BMD_Change | BH2: Followup_Tscore_le_-2.5 | BI2: Incident_Fracture | BJ2: Incident_Fracture_Date | BK2: Fracture_Site | BL2: Fracture_Type | BM2: Fracture_Evidence_Source | BN2: Composite_Osteoporosis_or_Fracture | BO2: Composite_Event_Date | BP2: Index_Date | BQ2: Last_Clinical_Contact_Date | BR2: Followup_End_Date | BS2: Followup_Duration_Days | BT2: Followup_Person_Years | BU2: Followup_>=24_Months | BV2: Death_During_Followup | BW2: Date_of_Death | BX2: Lost_to_Followup | BY2: Censoring_Reason | BZ2: Age_Group | CA2: CKD_Subgroup | CB2: Diabetes_Subgroup | CC2: Sex_Subgroup | CD2: Data_Extractor | CE2: Notes
A3: EXAMPLE-001 | B3: JUH | C3: Yes | E3: 68 | F3: Female | G3: Jordanian | H3: 160 | I3: 72 | J3: =IF(AND(N(H3)>0,N(I3)>0),ROUND(I3/(H3/100)^2,1),"") -> 28.1 | K3: Never | L3: No | M3: Yes | N3: No | O3: Atrial fibrillation | P3: Warfarin | Q3: Warfarin | R3: 42809 | T3: 74 | U3: =IF(N(T3)=0,"",IF(T3<12,"Under 12 months",IF(T3<36,"12-35 months",IF(T3<60,"36-59 months","≥60 months")))) -> ≥60 months | W3: 2.6 | X3: Yes | Y3: No | AA3: No | AB3: No | AC3: No | AD3: Yes | AE3: Yes | AF3: No | AG3: No | AH3: No | AI3: No | AJ3: Yes - omeprazole 20 mg, 3 yrs | AK3: No | AL3: No | AM3: No | AN3: No | AO3: Heart failure | AP3: No | AQ3: Unknown | AR3: Yes | AS3: 42857 | AT3: -1.2 | AU3: -1.4 | AV3: -1.1 | AW3: L1-L4 0.95 g/cm2; FN 0.71 g/cm2 | AX3: Yes | AY3: 44732 | AZ3: DEXA | BA3: M81.0 | BB3: 44732 | BC3: -2.6 | BD3: -2.2 | BE3: -1.9 | BF3: L1-L4 0.82 g/cm2; FN 0.62 g/cm2 | BG3: L1-L4 -13.7% | BH3: =IF(COUNT(BC3:BE3)=0,"",IF(MIN(BC3:BE3)<=-2.5,"Yes","No")) -> Yes | BI3: No | BN3: =IF(OR(AX3="Yes",BI3="Yes"),"Yes",IF(AND(AX3="No",BI3="No"),"No",IF(AND(AX3="",BI3=""),"","Unknown"))) -> Yes | BO3: =IF(COUNT(AY3,BJ3)=0,"",MIN(AY3,BJ3)) -> 44732 | BP3: 42809 | BQ3: 45301 | BR3: 44732 | BS3: =IF(AND(N(BP3)>0,N(BR3)>0),BR3-BP3,"") -> 1923 | BT3: =IF(BS3="","",ROUND(BS3/365.25,2)) -> 5.26 | BU3: =IF(BS3="","",IF(BS3>=730.5,"Yes","No")) -> Yes | BV3: No | BX3: No | BZ3: =IF(N(E3)=0,"",IF(E3<65,"Under 65","≥65")) -> ≥65 | CA3: =IF(OR(AC3="Yes",AC3="No"),AC3,"") -> No | CB3: =IF(OR(AD3="Yes",AD3="No"),AD3,"") -> Yes | CC3: =IF(F3="","",F3) -> Female | CD3: TA | CE3: Example row - delete before analysis
J4: =IF(AND(N(H4)>0,N(I4)>0),ROUND(I4/(H4/100)^2,1),"") | U4: =IF(N(T4)=0,"",IF(T4<12,"Under 12 months",IF(T4<36,"12-35 months",IF(T4<60,"36-59 months","≥60 months")))) | BH4: =IF(COUNT(BC4:BE4)=0,"",IF(MIN(BC4:BE4)<=-2.5,"Yes","No")) | BN4: =IF(OR(AX4="Yes",BI4="Yes"),"Yes",IF(AND(AX4="No",BI4="No"),"No",IF(AND(AX4="",BI4=""),"","Unknown"))) | BO4: =IF(COUNT(AY4,BJ4)=0,"",MIN(AY4,BJ4)) | BS4: =IF(AND(N(BP4)>0,N(BR4)>0),BR4-BP4,"") | BT4: =IF(BS4="","",ROUND(BS4/365.25,2)) | BU4: =IF(BS4="","",IF(BS4>=730.5,"Yes","No")) | BZ4: =IF(N(E4)=0,"",IF(E4<65,"Under 65","≥65")) | CA4: =IF(OR(AC4="Yes",AC4="No"),AC4,"") | CB4: =IF(OR(AD4="Yes",AD4="No"),AD4,"") | CC4: =IF(F4="","",F4)
J5: =IF(AND(N(H5)>0,N(I5)>0),ROUND(I5/(H5/100)^2,1),"") | U5: =IF(N(T5)=0,"",IF(T5<12,"Under 12 months",IF(T5<36,"12-35 months",IF(T5<60,"36-59 months","≥60 months")))) | BH5: =IF(COUNT(BC5:BE5)=0,"",IF(MIN(BC5:BE5)<=-2.5,"Yes","No")) | BN5: =IF(OR(AX5="Yes",BI5="Yes"),"Yes",IF(AND(AX5="No",BI5="No"),"No",IF(AND(AX5="",BI5=""),"","Unknown"))) | BO5: =IF(COUNT(AY5,BJ5)=0,"",MIN(AY5,BJ5)) | BS5: =IF(AND(N(BP5)>0,N(BR5)>0),BR5-BP5,"") | BT5: =IF(BS5="","",ROUND(BS5/365.25,2)) | BU5: =IF(BS5="","",IF(BS5>=730.5,"Yes","No")) | BZ5: =IF(N(E5)=0,"",IF(E5<65,"Under 65","≥65")) | CA5: =IF(OR(AC5="Yes",AC5="No"),AC5,"") | CB5: =IF(OR(AD5="Yes",AD5="No"),AD5,"") | CC5: =IF(F5="","",F5)
J6: =IF(AND(N(H6)>0,N(I6)>0),ROUND(I6/(H6/100)^2,1),"") | U6: =IF(N(T6)=0,"",IF(T6<12,"Under 12 months",IF(T6<36,"12-35 months",IF(T6<60,"36-59 months","≥60 months")))) | BH6: =IF(COUNT(BC6:BE6)=0,"",IF(MIN(BC6:BE6)<=-2.5,"Yes","No")) | BN6: =IF(OR(AX6="Yes",BI6="Yes"),"Yes",IF(AND(AX6="No",BI6="No"),"No",IF(AND(AX6="",BI6=""),"","Unknown"))) | BO6: =IF(COUNT(AY6,BJ6)=0,"",MIN(AY6,BJ6)) | BS6: =IF(AND(N(BP6)>0,N(BR6)>0),BR6-BP6,"") | BT6: =IF(BS6="","",ROUND(BS6/365.25,2)) | BU6: =IF(BS6="","",IF(BS6>=730.5,"Yes","No")) | BZ6: =IF(N(E6)=0,"",IF(E6<65,"Under 65","≥65")) | CA6: =IF(OR(AC6="Yes",AC6="No"),AC6,"") | CB6: =IF(OR(AD6="Yes",AD6="No"),AD6,"") | CC6: =IF(F6="","",F6)
J7: =IF(AND(N(H7)>0,N(I7)>0),ROUND(I7/(H7/100)^2,1),"") | U7: =IF(N(T7)=0,"",IF(T7<12,"Under 12 months",IF(T7<36,"12-35 months",IF(T7<60,"36-59 months","≥60 months")))) | BH7: =IF(COUNT(BC7:BE7)=0,"",IF(MIN(BC7:BE7)<=-2.5,"Yes","No")) | BN7: =IF(OR(AX7="Yes",BI7="Yes"),"Yes",IF(AND(AX7="No",BI7="No"),"No",IF(AND(AX7="",BI7=""),"","Unknown"))) | BO7: =IF(COUNT(AY7,BJ7)=0,"",MIN(AY7,BJ7)) | BS7: =IF(AND(N(BP7)>0,N(BR7)>0),BR7-BP7,"") | BT7: =IF(BS7="","",ROUND(BS7/365.25,2)) | BU7: =IF(BS7="","",IF(BS7>=730.5,"Yes","No")) | BZ7: =IF(N(E7)=0,"",IF(E7<65,"Under 65","≥65")) | CA7: =IF(OR(AC7="Yes",AC7="No"),AC7,"") | CB7: =IF(OR(AD7="Yes",AD7="No"),AD7,"") | CC7: =IF(F7="","",F7)
J8: =IF(AND(N(H8)>0,N(I8)>0),ROUND(I8/(H8/100)^2,1),"") | U8: =IF(N(T8)=0,"",IF(T8<12,"Under 12 months",IF(T8<36,"12-35 months",IF(T8<60,"36-59 months","≥60 months")))) | BH8: =IF(COUNT(BC8:BE8)=0,"",IF(MIN(BC8:BE8)<=-2.5,"Yes","No")) | BN8: =IF(OR(AX8="Yes",BI8="Yes"),"Yes",IF(AND(AX8="No",BI8="No"),"No",IF(AND(AX8="",BI8=""),"","Unknown"))) | BO8: =IF(COUNT(AY8,BJ8)=0,"",MIN(AY8,BJ8)) | BS8: =IF(AND(N(BP8)>0,N(BR8)>0),BR8-BP8,"") | BT8: =IF(BS8="","",ROUND(BS8/365.25,2)) | BU8: =IF(BS8="","",IF(BS8>=730.5,"Yes","No")) | BZ8: =IF(N(E8)=0,"",IF(E8<65,"Under 65","≥65")) | CA8: =IF(OR(AC8="Yes",AC8="No"),AC8,"") | CB8: =IF(OR(AD8="Yes",AD8="No"),AD8,"") | CC8: =IF(F8="","",F8)
J9: =IF(AND(N(H9)>0,N(I9)>0),ROUND(I9/(H9/100)^2,1),"") | U9: =IF(N(T9)=0,"",IF(T9<12,"Under 12 months",IF(T9<36,"12-35 months",IF(T9<60,"36-59 months","≥60 months")))) | BH9: =IF(COUNT(BC9:BE9)=0,"",IF(MIN(BC9:BE9)<=-2.5,"Yes","No")) | BN9: =IF(OR(AX9="Yes",BI9="Yes"),"Yes",IF(AND(AX9="No",BI9="No"),"No",IF(AND(AX9="",BI9=""),"","Unknown"))) | BO9: =IF(COUNT(AY9,BJ9)=0,"",MIN(AY9,BJ9)) | BS9: =IF(AND(N(BP9)>0,N(BR9)>0),BR9-BP9,"") | BT9: =IF(BS9="","",ROUND(BS9/365.25,2)) | BU9: =IF(BS9="","",IF(BS9>=730.5,"Yes","No")) | BZ9: =IF(N(E9)=0,"",IF(E9<65,"Under 65","≥65")) | CA9: =IF(OR(AC9="Yes",AC9="No"),AC9,"") | CB9: =IF(OR(AD9="Yes",AD9="No"),AD9,"") | CC9: =IF(F9="","",F9)
J10: =IF(AND(N(H10)>0,N(I10)>0),ROUND(I10/(H10/100)^2,1),"") | U10: =IF(N(T10)=0,"",IF(T10<12,"Under 12 months",IF(T10<36,"12-35 months",IF(T10<60,"36-59 months","≥60 months")))) | BH10: =IF(COUNT(BC10:BE10)=0,"",IF(MIN(BC10:BE10)<=-2.5,"Yes","No")) | BN10: =IF(OR(AX10="Yes",BI10="Yes"),"Yes",IF(AND(AX10="No",BI10="No"),"No",IF(AND(AX10="",BI10=""),"","Unknown"))) | BO10: =IF(COUNT(AY10,BJ10)=0,"",MIN(AY10,BJ10)) | BS10: =IF(AND(N(BP10)>0,N(BR10)>0),BR10-BP10,"") | BT10: =IF(BS10="","",ROUND(BS10/365.25,2)) | BU10: =IF(BS10="","",IF(BS10>=730.5,"Yes","No")) | BZ10: =IF(N(E10)=0,"",IF(E10<65,"Under 65","≥65")) | CA10: =IF(OR(AC10="Yes",AC10="No"),AC10,"") | CB10: =IF(OR(AD10="Yes",AD10="No"),AD10,"") | CC10: =IF(F10="","",F10)
J11: =IF(AND(N(H11)>0,N(I11)>0),ROUND(I11/(H11/100)^2,1),"") | U11: =IF(N(T11)=0,"",IF(T11<12,"Under 12 months",IF(T11<36,"12-35 months",IF(T11<60,"36-59 months","≥60 months")))) | BH11: =IF(COUNT(BC11:BE11)=0,"",IF(MIN(BC11:BE11)<=-2.5,"Yes","No")) | BN11: =IF(OR(AX11="Yes",BI11="Yes"),"Yes",IF(AND(AX11="No",BI11="No"),"No",IF(AND(AX11="",BI11=""),"","Unknown"))) | BO11: =IF(COUNT(AY11,BJ11)=0,"",MIN(AY11,BJ11)) | BS11: =IF(AND(N(BP11)>0,N(BR11)>0),BR11-BP11,"") | BT11: =IF(BS11="","",ROUND(BS11/365.25,2)) | BU11: =IF(BS11="","",IF(BS11>=730.5,"Yes","No")) | BZ11: =IF(N(E11)=0,"",IF(E11<65,"Under 65","≥65")) | CA11: =IF(OR(AC11="Yes",AC11="No"),AC11,"") | CB11: =IF(OR(AD11="Yes",AD11="No"),AD11,"") | CC11: =IF(F11="","",F11)
J12: =IF(AND(N(H12)>0,N(I12)>0),ROUND(I12/(H12/100)^2,1),"") | U12: =IF(N(T12)=0,"",IF(T12<12,"Under 12 months",IF(T12<36,"12-35 months",IF(T12<60,"36-59 months","≥60 months")))) | BH12: =IF(COUNT(BC12:BE12)=0,"",IF(MIN(BC12:BE12)<=-2.5,"Yes","No")) | BN12: =IF(OR(AX12="Yes",BI12="Yes"),"Yes",IF(AND(AX12="No",BI12="No"),"No",IF(AND(AX12="",BI12=""),"","Unknown"))) | BO12: =IF(COUNT(AY12,BJ12)=0,"",MIN(AY12,BJ12)) | BS12: =IF(AND(N(BP12)>0,N(BR12)>0),BR12-BP12,"") | BT12: =IF(BS12="","",ROUND(BS12/365.25,2)) | BU12: =IF(BS12="","",IF(BS12>=730.5,"Yes","No")) | BZ12: =IF(N(E12)=0,"",IF(E12<65,"Under 65","≥65")) | CA12: =IF(OR(AC12="Yes",AC12="No"),AC12,"") | CB12: =IF(OR(AD12="Yes",AD12="No"),AD12,"") | CC12: =IF(F12="","",F12)
J13: =IF(AND(N(H13)>0,N(I13)>0),ROUND(I13/(H13/100)^2,1),"") | U13: =IF(N(T13)=0,"",IF(T13<12,"Under 12 months",IF(T13<36,"12-35 months",IF(T13<60,"36-59 months","≥60 months")))) | BH13: =IF(COUNT(BC13:BE13)=0,"",IF(MIN(BC13:BE13)<=-2.5,"Yes","No")) | BN13: =IF(OR(AX13="Yes",BI13="Yes"),"Yes",IF(AND(AX13="No",BI13="No"),"No",IF(AND(AX13="",BI13=""),"","Unknown"))) | BO13: =IF(COUNT(AY13,BJ13)=0,"",MIN(AY13,BJ13)) | BS13: =IF(AND(N(BP13)>0,N(BR13)>0),BR13-BP13,"") | BT13: =IF(BS13="","",ROUND(BS13/365.25,2)) | BU13: =IF(BS13="","",IF(BS13>=730.5,"Yes","No")) | BZ13: =IF(N(E13)=0,"",IF(E13<65,"Under 65","≥65")) | CA13: =IF(OR(AC13="Yes",AC13="No"),AC13,"") | CB13: =IF(OR(AD13="Yes",AD13="No"),AD13,"") | CC13: =IF(F13="","",F13)
J14: =IF(AND(N(H14)>0,N(I14)>0),ROUND(I14/(H14/100)^2,1),"") | U14: =IF(N(T14)=0,"",IF(T14<12,"Under 12 months",IF(T14<36,"12-35 months",IF(T14<60,"36-59 months","≥60 months")))) | BH14: =IF(COUNT(BC14:BE14)=0,"",IF(MIN(BC14:BE14)<=-2.5,"Yes","No")) | BN14: =IF(OR(AX14="Yes",BI14="Yes"),"Yes",IF(AND(AX14="No",BI14="No"),"No",IF(AND(AX14="",BI14=""),"","Unknown"))) | BO14: =IF(COUNT(AY14,BJ14)=0,"",MIN(AY14,BJ14)) | BS14: =IF(AND(N(BP14)>0,N(BR14)>0),BR14-BP14,"") | BT14: =IF(BS14="","",ROUND(BS14/365.25,2)) | BU14: =IF(BS14="","",IF(BS14>=730.5,"Yes","No")) | BZ14: =IF(N(E14)=0,"",IF(E14<65,"Under 65","≥65")) | CA14: =IF(OR(AC14="Yes",AC14="No"),AC14,"") | CB14: =IF(OR(AD14="Yes",AD14="No"),AD14,"") | CC14: =IF(F14="","",F14)
J15: =IF(AND(N(H15)>0,N(I15)>0),ROUND(I15/(H15/100)^2,1),"") | U15: =IF(N(T15)=0,"",IF(T15<12,"Under 12 months",IF(T15<36,"12-35 months",IF(T15<60,"36-59 months","≥60 months")))) | BH15: =IF(COUNT(BC15:BE15)=0,"",IF(MIN(BC15:BE15)<=-2.5,"Yes","No")) | BN15: =IF(OR(AX15="Yes",BI15="Yes"),"Yes",IF(AND(AX15="No",BI15="No"),"No",IF(AND(AX15="",BI15=""),"","Unknown"))) | BO15: =IF(COUNT(AY15,BJ15)=0,"",MIN(AY15,BJ15)) | BS15: =IF(AND(N(BP15)>0,N(BR15)>0),BR15-BP15,"") | BT15: =IF(BS15="","",ROUND(BS15/365.25,2)) | BU15: =IF(BS15="","",IF(BS15>=730.5,"Yes","No")) | BZ15: =IF(N(E15)=0,"",IF(E15<65,"Under 65","≥65")) | CA15: =IF(OR(AC15="Yes",AC15="No"),AC15,"") | CB15: =IF(OR(AD15="Yes",AD15="No"),AD15,"") | CC15: =IF(F15="","",F15)
... J1003: =IF(AND(N(H1003)>0,N(I1003)>0),ROUND(I1003/(H1003/100)^2,1),"") | U1003: =IF(N(T1003)=0,"",IF(T1003<12,"Under 12 months",IF(T1003<36,"12-35 months",IF(T1003<60,"36-59 months","≥60 months")))) | BH1003: =IF(COUNT(BC1003:BE1003)=0,"",IF(MIN(BC1003:BE1003)<=-2.5,"Yes","No")) | BN1003: =IF(OR(AX1003="Yes",BI1003="Yes"),"Yes",IF(AND(AX1003="No",BI1003="No"),"No",IF(AND(AX1003="",BI1003=""),"","Unknown"))) | BO1003: =IF(COUNT(AY1003,BJ1003)=0,"",MIN(AY1003,BJ1003)) | BS1003: =IF(AND(N(BP1003)>0,N(BR1003)>0),BR1003-BP1003,"") | BT1003: =IF(BS1003="","",ROUND(BS1003/365.25,2)) | BU1003: =IF(BS1003="","",IF(BS1003>=730.5,"Yes","No")) | BZ1003: =IF(N(E1003)=0,"",IF(E1003<65,"Under 65","≥65")) | CA1003: =IF(OR(AC1003="Yes",AC1003="No"),AC1003,"") | CB1003: =IF(OR(AD1003="Yes",AD1003="No"),AD1003,"") | CC1003: =IF(F1003="","",F1003)

Sheet Screening_Log
A1: Screening_ID | B1: Hospital_Source | C1: Record_Reviewed | D1: Age_>=18 | E1: Exposure_Criteria_Met | F1: Baseline_Data_Adequate | G1: Exclusion_Criterion | H1: Eligible | I1: Exclusion_Reason | J1: Study_ID_Assigned
A2: SCR-EX-001 | B2: JUH | C2: Yes | D2: Yes | E2: Yes | F2: Yes | G2: No | H2: =IF(COUNTA(C2:G2)=0,"",IF(AND(C2="Yes",D2="Yes",E2="Yes",F2="Yes",G2="No"),"Yes","No")) -> Yes | J2: EXAMPLE-001
H3: =IF(COUNTA(C3:G3)=0,"",IF(AND(C3="Yes",D3="Yes",E3="Yes",F3="Yes",G3="No"),"Yes","No"))
H4: =IF(COUNTA(C4:G4)=0,"",IF(AND(C4="Yes",D4="Yes",E4="Yes",F4="Yes",G4="No"),"Yes","No"))
H5: =IF(COUNTA(C5:G5)=0,"",IF(AND(C5="Yes",D5="Yes",E5="Yes",F5="Yes",G5="No"),"Yes","No"))
H6: =IF(COUNTA(C6:G6)=0,"",IF(AND(C6="Yes",D6="Yes",E6="Yes",F6="Yes",G6="No"),"Yes","No"))
H7: =IF(COUNTA(C7:G7)=0,"",IF(AND(C7="Yes",D7="Yes",E7="Yes",F7="Yes",G7="No"),"Yes","No"))
H8: =IF(COUNTA(C8:G8)=0,"",IF(AND(C8="Yes",D8="Yes",E8="Yes",F8="Yes",G8="No"),"Yes","No"))
H9: =IF(COUNTA(C9:G9)=0,"",IF(AND(C9="Yes",D9="Yes",E9="Yes",F9="Yes",G9="No"),"Yes","No"))
H10: =IF(COUNTA(C10:G10)=0,"",IF(AND(C10="Yes",D10="Yes",E10="Yes",F10="Yes",G10="No"),"Yes","No"))
H11: =IF(COUNTA(C11:G11)=0,"",IF(AND(C11="Yes",D11="Yes",E11="Yes",F11="Yes",G11="No"),"Yes","No"))
H12: =IF(COUNTA(C12:G12)=0,"",IF(AND(C12="Yes",D12="Yes",E12="Yes",F12="Yes",G12="No"),"Yes","No"))
H13: =IF(COUNTA(C13:G13)=0,"",IF(AND(C13="Yes",D13="Yes",E13="Yes",F13="Yes",G13="No"),"Yes","No"))
H14: =IF(COUNTA(C14:G14)=0,"",IF(AND(C14="Yes",D14="Yes",E14="Yes",F14="Yes",G14="No"),"Yes","No"))
... H2001: =IF(COUNTA(C2001:G2001)=0,"",IF(AND(C2001="Yes",D2001="Yes",E2001="Yes",F2001="Yes",G2001="No"),"Yes","No"))

Sheet Data_Dictionary
A1: Variable_Name | B1: Section | C1: Full_Definition | D1: Data_Type | E1: Allowed_Values_or_Units | F1: Data_Source | G1: Missing_Value_Code | H1: Notes
A2: Study_ID | B2: A. Screening, ID & demographics | C2: Anonymous study code; no patient name or national ID in the analysis sheet. | D2: Text | E2: Free text | F2: Medical record (demographics) | G2: Leave blank = not recorded
A3: Hospital_Source | B3: A. Screening, ID & demographics | C3: Jordan University Hospital (JUH) / King Hussein Cancer Center (KHCC). | D3: Categorical | E3: JUH / KHCC | F3: Medical record (demographics) | G3: Leave blank = not recorded
A4: Eligible | B4: A. Screening, ID & demographics | C4: Yes / No. | D4: Categorical | E4: Yes / No | F4: Medical record (demographics) | G4: Leave blank = not recorded
A5: Exclusion_Reason | B5: A. Screening, ID & demographics | C5: Record the protocol-defined reason if excluded. | D5: Text | E5: Free text | F5: Medical record (demographics) | G5: Leave blank = not recorded
A6: Age_at_Index | B6: A. Screening, ID & demographics | C6: Years; proposal specifies adults aged >=18 years. | D6: Numeric | E6: Years (>=18) | F6: Medical record (demographics) | G6: Leave blank = not recorded
A7: Sex | B7: A. Screening, ID & demographics | C7: Male / Female, as recorded. | D7: Categorical | E7: Male / Female | F7: Medical record (demographics) | G7: Leave blank = not recorded
A8: Nationality | B8: A. Screening, ID & demographics | C8: As documented, if available; listed in proposal Section 15. | D8: Text | E8: Free text | F8: Medical record (demographics) | G8: Leave blank = not recorded
A9: Height_cm | B9: A. Screening, ID & demographics | C9: Height in cm, if available. | D9: Numeric | E9: cm | F9: Medical record (demographics) | G9: Leave blank = not recorded
A10: Weight_kg | B10: A. Screening, ID & demographics | C10: Weight in kg, if available. | D10: Numeric | E10: kg | F10: Medical record (demographics) | G10: Leave blank = not recorded
A11: BMI | B11: A. Screening, ID & demographics | C11: Auto-calculated: weight (kg) / height (m)^2. | D11: Derived (formula) | E11: kg/m2 | F11: Derived | G11: Blank if inputs missing | H11: Auto-calculated in Patient_Data - do not enter manually
A12: Smoking_Status | B12: A. Screening, ID & demographics | C12: Current / Former / Never / Unknown. | D12: Categorical | E12: Current / Former / Never / Unknown | F12: Medical record (demographics) | G12: Unknown
A13: Alcohol_Use | B13: A. Screening, ID & demographics | C13: Yes / No / Unknown, where documented. | D13: Categorical | E13: Yes / No / Unknown | F13: Medical record (demographics) | G13: Unknown
A14: Atrial_Fibrillation | B14: B. Cardiac indication & anticoagulant exposure | C14: Yes / No / Unknown. | D14: Categorical | E14: Yes / No / Unknown | F14: Prescription / medication administration / pharmacy records, clinical notes | G14: Unknown
A15: Valvular_Heart_Disease | B15: B. Cardiac indication & anticoagulant exposure | C15: Yes / No / Unknown; specify type if available (e.g. 'Yes - mechanical mitral valve'). | D15: Text | E15: Free text | F15: Prescription / medication administration / pharmacy records, clinical notes | G15: Leave blank = not recorded
A16: Anticoagulation_Indication | B16: B. Cardiac indication & anticoagulant exposure | C16: Atrial fibrillation, valvular disease, VTE, or other documented indication. | D16: Categorical | E16: Atrial fibrillation / Valvular heart disease / VTE / Other / Unknown | F16: Prescription / medication administration / pharmacy records, clinical notes | G16: Unknown
A17: Anticoagulant_Group | B17: B. Cardiac indication & anticoagulant exposure | C17: Warfarin / alternative anticoagulant / no anticoagulant; finalize comparator with supervisor. | D17: Categorical | E17: Warfarin / Alternative anticoagulant / No anticoagulant | F17: Prescription / medication administration / pharmacy records, clinical notes | G17: Leave blank = not recorded | H17: Comparator definition to be confirmed with supervisor (non-users vs DOAC users vs both).
A18: Specific_Anticoagulant | B18: B. Cardiac indication & anticoagulant exposure | C18: Warfarin, apixaban, rivaroxaban, dabigatran, edoxaban, heparin, none, or other. | D18: Categorical | E18: Warfarin / Apixaban / Rivaroxaban / Dabigatran / Edoxaban / Heparin / None / Other | F18: Prescription / medication administration / pharmacy records, clinical notes | G18: Leave blank = not recorded
A19: Exposure_Start_Date | B19: B. Cardiac indication & anticoagulant exposure | C19: Date of warfarin or comparator exposure; define consistently across groups. | D19: Date (dd/mm/yyyy) | E19: dd/mm/yyyy | F19: Prescription / medication administration / pharmacy records, clinical notes | G19: Leave blank = not recorded
A20: Exposure_End_Date | B20: B. Cardiac indication & anticoagulant exposure | C20: Date treatment stopped or changed, if applicable. | D20: Date (dd/mm/yyyy) | E20: dd/mm/yyyy | F20: Prescription / medication administration / pharmacy records, clinical notes | G20: Leave blank = not recorded
A21: Warfarin_Duration_Months | B21: B. Cardiac indication & anticoagulant exposure | C21: Cumulative duration in months (continuous or intermittent), based on prescription/administration/clinical records. | D21: Numeric | E21: Months (>=12 for inclusion) | F21: Prescription / medication administration / pharmacy records, clinical notes | G21: Leave blank = not recorded
A22: Warfarin_Duration_Category | B22: B. Cardiac indication & anticoagulant exposure | C22: Auto: 12-35 / 36-59 / ≥60 months (Under 12 flagged: does not meet inclusion). | D22: Derived (formula) | F22: Derived | G22: Blank if inputs missing | H22: Auto-calculated in Patient_Data - do not enter manually
A23: Warfarin_Cumulative_Dose | B23: B. Cardiac indication & anticoagulant exposure | C23: Where available; record units and time period (e.g. '18,500 mg over 74 months'). | D23: Text | E23: Free text | F23: Prescription / medication administration / pharmacy records, clinical notes | G23: Leave blank = not recorded
A24: Mean_INR | B24: B. Cardiac indication & anticoagulant exposure | C24: Where available; define how mean INR is calculated. | D24: Numeric | E24: INR units | F24: Prescription / medication administration / pharmacy records, clinical notes | G24: Leave blank = not recorded
A25: INR_Monitoring_Available | B25: B. Cardiac indication & anticoagulant exposure | C25: Yes / No. | D25: Categorical | E25: Yes / No | F25: Prescription / medication administration / pharmacy records, clinical notes | G25: Leave blank = not recorded
A26: Previous_Anticoagulant_Use | B26: B. Cardiac indication & anticoagulant exposure | C26: Yes / No / Unknown; specify drug and dates if available. | D26: Text | E26: Free text | F26: Prescription / medication administration / pharmacy records, clinical notes | G26: Leave blank = not recorded
A27: Drug_Switch_or_Discontinuation_Date | B27: B. Cardiac indication & anticoagulant exposure | C27: Date and reason, if documented. | D27: Text | E27: Free text | F27: Prescription / medication administration / pharmacy records, clinical notes | G27: Leave blank = not recorded
A28: Preexisting_Osteoporosis | B28: C. Baseline eligibility & medical history | C28: Yes / No / Unknown before index date. | D28: Categorical | E28: Yes / No / Unknown | F28: Medical record (problem list, notes, medications) | G28: Unknown
A29: Preexisting_Fragility_Fracture | B29: C. Baseline eligibility & medical history | C29: Yes / No / Unknown before index date; record site/date. | D29: Text | E29: Free text | F29: Medical record (problem list, notes, medications) | G29: Leave blank = not recorded | H29: Exclusion criterion AND listed confounder in proposal - clarify rule with supervisor.
A30: Chronic_Kidney_Disease | B30: C. Baseline eligibility & medical history | C30: Yes / No / Unknown. | D30: Categorical | E30: Yes / No / Unknown | F30: Medical record (problem list, notes, medications) | G30: Unknown
A31: Diabetes_Mellitus | B31: C. Baseline eligibility & medical history | C31: Yes / No / Unknown. | D31: Categorical | E31: Yes / No / Unknown | F31: Medical record (problem list, notes, medications) | G31: Unknown
A32: Hypertension | B32: C. Baseline eligibility & medical history | C32: Yes / No / Unknown. | D32: Categorical | E32: Yes / No / Unknown | F32: Medical record (problem list, notes, medications) | G32: Unknown
A33: Rheumatoid_Arthritis | B33: C. Baseline eligibility & medical history | C33: Yes / No / Unknown. | D33: Categorical | E33: Yes / No / Unknown | F33: Medical record (problem list, notes, medications) | G33: Unknown
A34: Inflammatory_Bowel_Disease | B34: C. Baseline eligibility & medical history | C34: Yes / No / Unknown. | D34: Categorical | E34: Yes / No / Unknown | F34: Medical record (problem list, notes, medications) | G34: Unknown
A35: Chronic_Liver_Disease | B35: C. Baseline eligibility & medical history | C35: Yes / No / Unknown. | D35: Categorical | E35: Yes / No / Unknown | F35: Medical record (problem list, notes, medications) | G35: Unknown
A36: Systemic_Corticosteroid_Use | B36: C. Baseline eligibility & medical history | C36: Yes / No / Unknown; dose/duration if available. | D36: Text | E36: Free text | F36: Medical record (problem list, notes, medications) | G36: Leave blank = not recorded
A37: PPI_Use | B37: C. Baseline eligibility & medical history | C37: Yes / No / Unknown; drug and duration if available. | D37: Text | E37: Free text | F37: Medical record (problem list, notes, medications) | G37: Leave blank = not recorded
A38: History_of_Falls | B38: C. Baseline eligibility & medical history | C38: Yes / No / Unknown. | D38: Categorical | E38: Yes / No / Unknown | F38: Medical record (problem list, notes, medications) | G38: Unknown
A39: Cancer_History | B39: C. Baseline eligibility & medical history | C39: Yes / No / Unknown; specify type. | D39: Text | E39: Free text | F39: Medical record (problem list, notes, medications) | G39: Leave blank = not recorded
A40: Bone_Metastases | B40: C. Baseline eligibility & medical history | C40: Yes / No / Unknown; relevant to exclusion criteria. | D40: Categorical | E40: Yes / No / Unknown | F40: Medical record (problem list, notes, medications) | G40: Unknown
...

Sheet Summary
A1: Warfarin & Osteoporosis / Fragility Fractures - Live Summary
A2: All figures update automatically from Patient_Data rows 4-1003 (example row 3 excluded). Counts restricted to Eligible = Yes.
A4: 1. Recruitment progress vs. target sample size
A5: Group | B5: Target (proposal) | C5: Eligible enrolled | D5: % of target
A6: Warfarin users | B6: 151 | C6: =COUNTIFS(Patient_Data!$C$4:$C$1003,"Yes",Patient_Data!$P$4:$P$1003,"Warfarin") -> 0 | D6: =IF(B6>0,C6/B6,0) -> 0
A7: Non-users / comparator (all non-warfarin groups) | B7: 302 | C7: =COUNTIFS(Patient_Data!$C$4:$C$1003,"Yes",Patient_Data!$P$4:$P$1003,"Alternative anticoagulant")+COUNTIFS(Patient_Data!$C$4:$C$1003,"Yes",Patient_Data!$P$4:$P$1003,"No anticoagulant") -> 0 | D7: =IF(B7>0,C7/B7,0) -> 0
A8: Total | B8: =B6+B7 -> 453 | C8: =C6+C7 -> 0 | D8: =IF(B8>0,C8/B8,0) -> 0
A9: Targets from proposal 'Study Size' (453 = 385 + 15% missing; 1:2 ratio). Blue = hard-coded input.
A10: Records screened (Screening_Log) | B10: =COUNTIF(Screening_Log!$C$3:$C$2001,"Yes") -> 0
A11: Screened eligible (Screening_Log) | B11: =COUNTIF(Screening_Log!$H$3:$H$2001,"Yes") -> 0
A12: Screened not eligible (Screening_Log) | B12: =COUNTIF(Screening_Log!$H$3:$H$2001,"No") -> 0
A14: 2. Baseline characteristics by group (Eligible = Yes)
A15: Characteristic | B15: Warfarin | C15: Alternative anticoagulant | D15: No anticoagulant | E15: All eligible
A16: N | B16: =COUNTIFS(Patient_Data!$C$4:$C$1003,"Yes",Patient_Data!$P$4:$P$1003,"Warfarin") -> 0 | C16: =COUNTIFS(Patient_Data!$C$4:$C$1003,"Yes",Patient_Data!$P$4:$P$1003,"Alternative anticoagulant") -> 0 | D16: =COUNTIFS(Patient_Data!$C$4:$C$1003,"Yes",Patient_Data!$P$4:$P$1003,"No anticoagulant") -> 0 | E16: =COUNTIFS(Patient_Data!$C$4:$C$1003,"Yes") -> 0
A17: Age, mean (years) | B17: =IFERROR(AVERAGEIFS(Patient_Data!$E$4:$E$1003,Patient_Data!$C$4:$C$1003,"Yes",Patient_Data!$P$4:$P$1003,"Warfarin"),"-") -> - | C17: =IFERROR(AVERAGEIFS(Patient_Data!$E$4:$E$1003,Patient_Data!$C$4:$C$1003,"Yes",Patient_Data!$P$4:$P$1003,"Alternative anticoagulant"),"-") -> - | D17: =IFERROR(AVERAGEIFS(Patient_Data!$E$4:$E$1003,Patient_Data!$C$4:$C$1003,"Yes",Patient_Data!$P$4:$P$1003,"No anticoagulant"),"-") -> - | E17: =IFERROR(AVERAGEIFS(Patient_Data!$E$4:$E$1003,Patient_Data!$C$4:$C$1003,"Yes"),"-") -> -
A18: Age ≥65, n | B18: =COUNTIFS(Patient_Data!$C$4:$C$1003,"Yes",Patient_Data!$P$4:$P$1003,"Warfarin",Patient_Data!$BZ$4:$BZ$1003,"≥65") -> 0 | C18: =COUNTIFS(Patient_Data!$C$4:$C$1003,"Yes",Patient_Data!$P$4:$P$1003,"Alternative anticoagulant",Patient_Data!$BZ$4:$BZ$1003,"≥65") -> 0 | D18: =COUNTIFS(Patient_Data!$C$4:$C$1003,"Yes",Patient_Data!$P$4:$P$1003,"No anticoagulant",Patient_Data!$BZ$4:$BZ$1003,"≥65") -> 0 | E18: =COUNTIFS(Patient_Data!$C$4:$C$1003,"Yes",Patient_Data!$BZ$4:$BZ$1003,"≥65") -> 0
A19: Female, n | B19: =COUNTIFS(Patient_Data!$C$4:$C$1003,"Yes",Patient_Data!$P$4:$P$1003,"Warfarin",Patient_Data!$F$4:$F$1003,"Female") -> 0 | C19: =COUNTIFS(Patient_Data!$C$4:$C$1003,"Yes",Patient_Data!$P$4:$P$1003,"Alternative anticoagulant",Patient_Data!$F$4:$F$1003,"Female") -> 0 | D19: =COUNTIFS(Patient_Data!$C$4:$C$1003,"Yes",Patient_Data!$P$4:$P$1003,"No anticoagulant",Patient_Data!$F$4:$F$1003,"Female") -> 0 | E19: =COUNTIFS(Patient_Data!$C$4:$C$1003,"Yes",Patient_Data!$F$4:$F$1003,"Female") -> 0
A20: BMI, mean (kg/m2) | B20: =IFERROR(AVERAGEIFS(Patient_Data!$J$4:$J$1003,Patient_Data!$C$4:$C$1003,"Yes",Patient_Data!$P$4:$P$1003,"Warfarin"),"-") -> - | C20: =IFERROR(AVERAGEIFS(Patient_Data!$J$4:$J$1003,Patient_Data!$C$4:$C$1003,"Yes",Patient_Data!$P$4:$P$1003,"Alternative anticoagulant"),"-") -> - | D20: =IFERROR(AVERAGEIFS(Patient_Data!$J$4:$J$1003,Patient_Data!$C$4:$C$1003,"Yes",Patient_Data!$P$4:$P$1003,"No anticoagulant"),"-") -> - | E20: =IFERROR(AVERAGEIFS(Patient_Data!$J$4:$J$1003,Patient_Data!$C$4:$C$1003,"Yes"),"-") -> -
A21: Current smoker, n | B21: =COUNTIFS(Patient_Data!$C$4:$C$1003,"Yes",Patient_Data!$P$4:$P$1003,"Warfarin",Patient_Data!$K$4:$K$1003,"Current") -> 0 | C21: =COUNTIFS(Patient_Data!$C$4:$C$1003,"Yes",Patient_Data!$P$4:$P$1003,"Alternative anticoagulant",Patient_Data!$K$4:$K$1003,"Current") -> 0 | D21: =COUNTIFS(Patient_Data!$C$4:$C$1003,"Yes",Patient_Data!$P$4:$P$1003,"No anticoagulant",Patient_Data!$K$4:$K$1003,"Current") -> 0 | E21: =COUNTIFS(Patient_Data!$C$4:$C$1003,"Yes",Patient_Data!$K$4:$K$1003,"Current") -> 0
A22: Alcohol use, n | B22: =COUNTIFS(Patient_Data!$C$4:$C$1003,"Yes",Patient_Data!$P$4:$P$1003,"Warfarin",Patient_Data!$L$4:$L$1003,"Yes") -> 0 | C22: =COUNTIFS(Patient_Data!$C$4:$C$1003,"Yes",Patient_Data!$P$4:$P$1003,"Alternative anticoagulant",Patient_Data!$L$4:$L$1003,"Yes") -> 0 | D22: =COUNTIFS(Patient_Data!$C$4:$C$1003,"Yes",Patient_Data!$P$4:$P$1003,"No anticoagulant",Patient_Data!$L$4:$L$1003,"Yes") -> 0 | E22: =COUNTIFS(Patient_Data!$C$4:$C$1003,"Yes",Patient_Data!$L$4:$L$1003,"Yes") -> 0
A23: Atrial fibrillation, n | B23: =COUNTIFS(Patient_Data!$C$4:$C$1003,"Yes",Patient_Data!$P$4:$P$1003,"Warfarin",Patient_Data!$M$4:$M$1003,"Yes") -> 0 | C23: =COUNTIFS(Patient_Data!$C$4:$C$1003,"Yes",Patient_Data!$P$4:$P$1003,"Alternative anticoagulant",Patient_Data!$M$4:$M$1003,"Yes") -> 0 | D23: =COUNTIFS(Patient_Data!$C$4:$C$1003,"Yes",Patient_Data!$P$4:$P$1003,"No anticoagulant",Patient_Data!$M$4:$M$1003,"Yes") -> 0 | E23: =COUNTIFS(Patient_Data!$C$4:$C$1003,"Yes",Patient_Data!$M$4:$M$1003,"Yes") -> 0
A24: Chronic kidney disease, n | B24: =COUNTIFS(Patient_Data!$C$4:$C$1003,"Yes",Patient_Data!$P$4:$P$1003,"Warfarin",Patient_Data!$AC$4:$AC$1003,"Yes") -> 0 | C24: =COUNTIFS(Patient_Data!$C$4:$C$1003,"Yes",Patient_Data!$P$4:$P$1003,"Alternative anticoagulant",Patient_Data!$AC$4:$AC$1003,"Yes") -> 0 | D24: =COUNTIFS(Patient_Data!$C$4:$C$1003,"Yes",Patient_Data!$P$4:$P$1003,"No anticoagulant",Patient_Data!$AC$4:$AC$1003,"Yes") -> 0 | E24: =COUNTIFS(Patient_Data!$C$4:$C$1003,"Yes",Patient_Data!$AC$4:$AC$1003,"Yes") -> 0
A25: Diabetes mellitus, n | B25: =COUNTIFS(Patient_Data!$C$4:$C$1003,"Yes",Patient_Data!$P$4:$P$1003,"Warfarin",Patient_Data!$AD$4:$AD$1003,"Yes") -> 0 | C25: =COUNTIFS(Patient_Data!$C$4:$C$1003,"Yes",Patient_Data!$P$4:$P$1003,"Alternative anticoagulant",Patient_Data!$AD$4:$AD$1003,"Yes") -> 0 | D25: =COUNTIFS(Patient_Data!$C$4:$C$1003,"Yes",Patient_Data!$P$4:$P$1003,"No anticoagulant",Patient_Data!$AD$4:$AD$1003,"Yes") -> 0 | E25: =COUNTIFS(Patient_Data!$C$4:$C$1003,"Yes",Patient_Data!$AD$4:$AD$1003,"Yes") -> 0
A26: Hypertension, n | B26: =COUNTIFS(Patient_Data!$C$4:$C$1003,"Yes",Patient_Data!$P$4:$P$1003,"Warfarin",Patient_Data!$AE$4:$AE$1003,"Yes") -> 0 | C26: =COUNTIFS(Patient_Data!$C$4:$C$1003,"Yes",Patient_Data!$P$4:$P$1003,"Alternative anticoagulant",Patient_Data!$AE$4:$AE$1003,"Yes") -> 0 | D26: =COUNTIFS(Patient_Data!$C$4:$C$1003,"Yes",Patient_Data!$P$4:$P$1003,"No anticoagulant",Patient_Data!$AE$4:$AE$1003,"Yes") -> 0 | E26: =COUNTIFS(Patient_Data!$C$4:$C$1003,"Yes",Patient_Data!$AE$4:$AE$1003,"Yes") -> 0
A27: History of falls, n | B27: =COUNTIFS(Patient_Data!$C$4:$C$1003,"Yes",Patient_Data!$P$4:$P$1003,"Warfarin",Patient_Data!$AK$4:$AK$1003,"Yes") -> 0 | C27: =COUNTIFS(Patient_Data!$C$4:$C$1003,"Yes",Patient_Data!$P$4:$P$1003,"Alternative anticoagulant",Patient_Data!$AK$4:$AK$1003,"Yes") -> 0 | D27: =COUNTIFS(Patient_Data!$C$4:$C$1003,"Yes",Patient_Data!$P$4:$P$1003,"No anticoagulant",Patient_Data!$AK$4:$AK$1003,"Yes") -> 0 | E27: =COUNTIFS(Patient_Data!$C$4:$C$1003,"Yes",Patient_Data!$AK$4:$AK$1003,"Yes") -> 0
A28: Calcium / vitamin D, n | B28: =COUNTIFS(Patient_Data!$C$4:$C$1003,"Yes",Patient_Data!$P$4:$P$1003,"Warfarin",Patient_Data!$AQ$4:$AQ$1003,"Yes") -> 0 | C28: =COUNTIFS(Patient_Data!$C$4:$C$1003,"Yes",Patient_Data!$P$4:$P$1003,"Alternative anticoagulant",Patient_Data!$AQ$4:$AQ$1003,"Yes") -> 0 | D28: =COUNTIFS(Patient_Data!$C$4:$C$1003,"Yes",Patient_Data!$P$4:$P$1003,"No anticoagulant",Patient_Data!$AQ$4:$AQ$1003,"Yes") -> 0 | E28: =COUNTIFS(Patient_Data!$C$4:$C$1003,"Yes",Patient_Data!$AQ$4:$AQ$1003,"Yes") -> 0
A29: Baseline DEXA available, n | B29: =COUNTIFS(Patient_Data!$C$4:$C$1003,"Yes",Patient_Data!$P$4:$P$1003,"Warfarin",Patient_Data!$AR$4:$AR$1003,"Yes") -> 0 | C29: =COUNTIFS(Patient_Data!$C$4:$C$1003,"Yes",Patient_Data!$P$4:$P$1003,"Alternative anticoagulant",Patient_Data!$AR$4:$AR$1003,"Yes") -> 0 | D29: =COUNTIFS(Patient_Data!$C$4:$C$1003,"Yes",Patient_Data!$P$4:$P$1003,"No anticoagulant",Patient_Data!$AR$4:$AR$1003,"Yes") -> 0 | E29: =COUNTIFS(Patient_Data!$C$4:$C$1003,"Yes",Patient_Data!$AR$4:$AR$1003,"Yes") -> 0
A30: INR monitoring available, n | B30: =COUNTIFS(Patient_Data!$C$4:$C$1003,"Yes",Patient_Data!$P$4:$P$1003,"Warfarin",Patient_Data!$X$4:$X$1003,"Yes") -> 0 | C30: =COUNTIFS(Patient_Data!$C$4:$C$1003,"Yes",Patient_Data!$P$4:$P$1003,"Alternative anticoagulant",Patient_Data!$X$4:$X$1003,"Yes") -> 0 | D30: =COUNTIFS(Patient_Data!$C$4:$C$1003,"Yes",Patient_Data!$P$4:$P$1003,"No anticoagulant",Patient_Data!$X$4:$X$1003,"Yes") -> 0 | E30: =COUNTIFS(Patient_Data!$C$4:$C$1003,"Yes",Patient_Data!$X$4:$X$1003,"Yes") -> 0
A31: Free-text Yes/No fields (corticosteroids, PPI, prior fracture) are not counted here - summarise in SPSS after coding.
A33: 3. Outcomes & incidence per 1,000 person-years (Eligible = Yes)
A34: Measure | B34: Warfarin | C34: Alternative anticoagulant | D34: No anticoagulant | E34: All eligible
A35: Person-years of follow-up | B35: =SUMIFS(Patient_Data!$BT$4:$BT$1003,Patient_Data!$C$4:$C$1003,"Yes",Patient_Data!$P$4:$P$1003,"Warfarin") -> 0 | C35: =SUMIFS(Patient_Data!$BT$4:$BT$1003,Patient_Data!$C$4:$C$1003,"Yes",Patient_Data!$P$4:$P$1003,"Alternative anticoagulant") -> 0 | D35: =SUMIFS(Patient_Data!$BT$4:$BT$1003,Patient_Data!$C$4:$C$1003,"Yes",Patient_Data!$P$4:$P$1003,"No anticoagulant") -> 0 | E35: =SUMIFS(Patient_Data!$BT$4:$BT$1003,Patient_Data!$C$4:$C$1003,"Yes") -> 0
A36: Incident osteoporosis - events, n | B36: =COUNTIFS(Patient_Data!$C$4:$C$1003,"Yes",Patient_Data!$P$4:$P$1003,"Warfarin",Patient_Data!$AX$4:$AX$1003,"Yes") -> 0 | C36: =COUNTIFS(Patient_Data!$C$4:$C$1003,"Yes",Patient_Data!$P$4:$P$1003,"Alternative anticoagulant",Patient_Data!$AX$4:$AX$1003,"Yes") -> 0 | D36: =COUNTIFS(Patient_Data!$C$4:$C$1003,"Yes",Patient_Data!$P$4:$P$1003,"No anticoagulant",Patient_Data!$AX$4:$AX$1003,"Yes") -> 0 | E36: =COUNTIFS(Patient_Data!$C$4:$C$1003,"Yes",Patient_Data!$AX$4:$AX$1003,"Yes") -> 0
A37: Incident osteoporosis - incidence / 1,000 PY | B37: =IF(B$35>0,B36/B$35*1000,"-") -> - | C37: =IF(C$35>0,C36/C$35*1000,"-") -> - | D37: =IF(D$35>0,D36/D$35*1000,"-") -> - | E37: =IF(E$35>0,E36/E$35*1000,"-") -> -
A38: Incident fracture - events, n | B38: =COUNTIFS(Patient_Data!$C$4:$C$1003,"Yes",Patient_Data!$P$4:$P$1003,"Warfarin",Patient_Data!$BI$4:$BI$1003,"Yes") -> 0 | C38: =COUNTIFS(Patient_Data!$C$4:$C$1003,"Yes",Patient_Data!$P$4:$P$1003,"Alternative anticoagulant",Patient_Data!$BI$4:$BI$1003,"Yes") -> 0 | D38: =COUNTIFS(Patient_Data!$C$4:$C$1003,"Yes",Patient_Data!$P$4:$P$1003,"No anticoagulant",Patient_Data!$BI$4:$BI$1003,"Yes") -> 0 | E38: =COUNTIFS(Patient_Data!$C$4:$C$1003,"Yes",Patient_Data!$BI$4:$BI$1003,"Yes") -> 0
A39: Incident fracture - incidence / 1,000 PY | B39: =IF(B$35>0,B38/B$35*1000,"-") -> - | C39: =IF(C$35>0,C38/C$35*1000,"-") -> - | D39: =IF(D$35>0,D38/D$35*1000,"-") -> - | E39: =IF(E$35>0,E38/E$35*1000,"-") -> -
A40: Composite osteoporosis or fracture - events, n | B40: =COUNTIFS(Patient_Data!$C$4:$C$1003,"Yes",Patient_Data!$P$4:$P$1003,"Warfarin",Patient_Data!$BN$4:$BN$1003,"Yes") -> 0 | C40: =COUNTIFS(Patient_Data!$C$4:$C$1003,"Yes",Patient_Data!$P$4:$P$1003,"Alternative anticoagulant",Patient_Data!$BN$4:$BN$1003,"Yes") -> 0 | D40: =COUNTIFS(Patient_Data!$C$4:$C$1003,"Yes",Patient_Data!$P$4:$P$1003,"No anticoagulant",Patient_Data!$BN$4:$BN$1003,"Yes") -> 0 | E40: =COUNTIFS(Patient_Data!$C$4:$C$1003,"Yes",Patient_Data!$BN$4:$BN$1003,"Yes") -> 0
A41: Composite osteoporosis or fracture - incidence / 1,000 PY | B41: =IF(B$35>0,B40/B$35*1000,"-") -> - | C41: =IF(C$35>0,C40/C$35*1000,"-") -> - | D41: =IF(D$35>0,D40/D$35*1000,"-") -> - | E41: =IF(E$35>0,E40/E$35*1000,"-") -> -
A42: Follow-up T-score <= -2.5 (DEXA-confirmed), n | B42: =COUNTIFS(Patient_Data!$C$4:$C$1003,"Yes",Patient_Data!$P$4:$P$1003,"Warfarin",Patient_Data!$BH$4:$BH$1003,"Yes") -> 0 | C42: =COUNTIFS(Patient_Data!$C$4:$C$1003,"Yes",Patient_Data!$P$4:$P$1003,"Alternative anticoagulant",Patient_Data!$BH$4:$BH$1003,"Yes") -> 0 | D42: =COUNTIFS(Patient_Data!$C$4:$C$1003,"Yes",Patient_Data!$P$4:$P$1003,"No anticoagulant",Patient_Data!$BH$4:$BH$1003,"Yes") -> 0 | E42: =COUNTIFS(Patient_Data!$C$4:$C$1003,"Yes",Patient_Data!$BH$4:$BH$1003,"Yes") -> 0
A43: Follow-up >= 24 months, n | B43: =COUNTIFS(Patient_Data!$C$4:$C$1003,"Yes",Patient_Data!$P$4:$P$1003,"Warfarin",Patient_Data!$BU$4:$BU$1003,"Yes") -> 0 | C43: =COUNTIFS(Patient_Data!$C$4:$C$1003,"Yes",Patient_Data!$P$4:$P$1003,"Alternative anticoagulant",Patient_Data!$BU$4:$BU$1003,"Yes") -> 0 | D43: =COUNTIFS(Patient_Data!$C$4:$C$1003,"Yes",Patient_Data!$P$4:$P$1003,"No anticoagulant",Patient_Data!$BU$4:$BU$1003,"Yes") -> 0 | E43: =COUNTIFS(Patient_Data!$C$4:$C$1003,"Yes",Patient_Data!$BU$4:$BU$1003,"Yes") -> 0
...

Sheet Protocol_Decisions
A1: # | B1: Issue | C1: Detail (from data collection form) | D1: Supervisor decision | E1: Date decided
A2: 1 | B2: Comparator group | C2: Proposal says 'non-users' in sample-size/analysis sections but discusses DOAC comparisons in the literature review. Confirm whether the control group is non-anticoagulant users, DOAC users, or both.
A3: 2 | B3: DEXA-based eligibility | C3: Requiring a DEXA scan or osteoporosis diagnosis during follow-up may select patients based on testing or outcome. Ask whether eligibility should instead require adequate records and baseline outcome-free status.
A4: 3 | B4: Prior fracture rule | C4: Proposal excludes prior fragility fracture but also lists it as a potential confounder. Clarify whether all prior fragility fractures are exclusionary.
A5: 4 | B5: Comparator exposure definitions | C5: Warfarin duration categories are specified, but matching duration definitions for comparator groups and rules for treatment switching/censoring need to be prespecified.
A6: 5 | B6: Confounder vs exclusion balance | C6: Several conditions are listed as exclusions and also as adjustment variables. Finalize which variables are exclusion criteria versus adjustment variables.
A7: 6 | B7: Index date definition | C7: Define Index_Date consistently for warfarin users and comparators (e.g. exposure start, or 12 months after start).
A8: 7 | B8: Study period | C8: Proposal leaves the record period blank ('from ----- to -----'). Fill in once approved.

Sheet Lists
A1: YN | B1: YNU | C1: Hospital | D1: Sex | E1: Smoking | F1: Indication | G1: Group | H1: Drug | I1: Method | J1: FxSite | K1: FxType | L1: FxSource | M1: Censor
A2: Yes | B2: Yes | C2: JUH | D2: Male | E2: Current | F2: Atrial fibrillation | G2: Warfarin | H2: Warfarin | I2: DEXA | J2: Hip | K2: Fragility/osteoporotic | L2: Medical record | M2: Study end
A3: No | B3: No | C3: KHCC | D3: Female | E3: Former | F3: Valvular heart disease | G3: Alternative anticoagulant | H3: Apixaban | I3: Clinical diagnosis | J3: Vertebral | K3: Traumatic | L3: Radiology report | M3: Death
B4: Unknown | E4: Never | F4: VTE | G4: No anticoagulant | H4: Rivaroxaban | I4: Both | J4: Distal radius | K4: Unclear | L4: Diagnostic code | M4: Last contact
E5: Unknown | F5: Other | H5: Dabigatran | I5: Unclear | J5: Other | L5: Other | M5: Treatment switch/stop
F6: Unknown | H6: Edoxaban | M6: Other
H7: Heparin
H8: None
H9: Other
